<?xml version="1.0" encoding="utf-8"?>
<mujoco>
	<compiler angle="radian" coordinate="local" inertiafromgeom="true"></compiler>
	<option timestep="0.002">
		<flag warmstart="enable"></flag>
	</option>
	
	<default>
		<joint damping="3" stiffness="0" armature="0" user="0"/>
		<geom solref="0.008 1" solimp="0.95 0.95 0.01" margin="0.001" user="0"/>
		<!-- <position ctrllimited="true"/> -->
	</default>
	
	<worldbody>
		<light directional="true" ambient="0.2 0.2 0.2" diffuse="0.8 0.8 0.8" specular="0.3 0.3 0.3" castshadow="false" pos="0 0 4" dir="0 0 -1" name="light0"></light>
	
		<geom name="ground" type="plane" pos="0 0 0" size="3 5 0.001" rgba=" .25 .26 .25 1"/>
		<body name="ground" pos="0 0 0">
			<site name="goal" type="sphere" size="0.08" pos="-1.223 1.36346 0.08" rgba="1 0 0 0.5"/>
		</body>
		<!-- <site name="camera_holder" type="capsule" size="0.02" fromto="0 0 0 0 0 6" rgba="0 1 0 0.1"/> -->
		
		<body name="obstacle">
			<geom type="cylinder" mass="10000" pos="1.1 0 1" size="0.05 1" rgba="0 0 1 1" />
		</body>
		
		<camera name="upper_camera" pos="0 0 6" />
		<body pos="0 0 0">
			<inertial diaginertia="0.3607 0.3607 0.3607" mass="3" pos="0 0 0"></inertial>
			<joint name="joint_1" type="hinge" axis="0 0 1" pos="0 0 0" limited="true" range="-5 5"/>
			<geom name="shoulder" type="capsule" size="0.03" fromto="0 0 0.16 0 1.2 0.16" rgba="0.91 0.18 0.78 1"/>
			<site name="connection_site_1" type="cylinder" size="0.05 0.1" pos="0 0 0.1" rgba="0.11 0.38 0.95 0.9"/>
			
			<body pos="0 0 0.08">
				<inertial diaginertia="0.2507 0.2507 0.2507" mass="3" pos="0 0 0"></inertial>
				<geom name="elbow" type="capsule" size="0.03" fromto="0 1.2 0 0 2.2 0" rgba="0.91 0.18 0.78 1"/>
				<site name="connection_site_2" type="cylinder" size="0.05 0.08" pos="0 1.2 0.05" rgba="0.11 0.38 0.95 0.9"/>
				<joint name="joint_2" type="hinge" axis="0 0 1" pos="0 1.2 0" limited="true" range="-5 5"/>
				<site name="end_site" type="sphere" size="0.03" pos="0 2.22 0" rgba="0 1 0 1"/>
			</body>
		</body>
	</worldbody>
	
	<actuator>
        <motor joint='joint_1' name='motor_1' ctrlrange="-5 5"/>
        <motor joint='joint_2' name='motor_2' ctrlrange="-5 5"/>
	</actuator>
	
	
</mujoco>
