<?xml version="1.0" encoding="utf-8"?>
<mujoco>
	<compiler angle="radian" coordinate="local" inertiafromgeom="true"></compiler>
	<option timestep="0.002">
		<flag warmstart="enable"></flag>
	</option>
	
	<default>
		<joint limited="true" damping="0" stiffness="0" armature=".1" user="0"/>
		<geom solref="0.008 1" solimp="0.95 0.95 0.01" margin="0.001" user="0"/>
		<position ctrllimited="true"/>
		
		<default class='0'>
			<geom friction="1 0.005 0.001" rgba=".75 .6 .5 1" contype="1" conaffinity="0"/>
		</default>
		
	</default>
	
	<worldbody>
		<light directional="true" ambient="0.2 0.2 0.2" diffuse="0.8 0.8 0.8" specular="0.3 0.3 0.3" castshadow="false" pos="0 0 4" dir="0 0 -1" name="light0"></light>
	
		<geom name="ground" type="plane" pos="0 0 0" size="3 5 0.001" rgba=" .25 .26 .25 1"/>
		<body name="ground" pos="0 0 0">
			<site name="goal" type="sphere" size="0.1" pos="-1.223 1.36346 0.08" rgba="1 0 0 0.5"/>
		</body>
		<!-- <site name="camera_holder" type="capsule" size="0.02" fromto="0 0 0 0 0 6" rgba="0 1 0 0.1"/> -->
		<camera name="upper_camera" pos="0 0 6" />
		<body pos="0 0 0">
			<inertial diaginertia="0.2725 0.2725 0.2725" mass="3" pos="0 0 0"></inertial>
			<joint name="joint_1" type="hinge" axis="0 0 1" pos="0 0 0" limited="true" range="-3 3"/>
			<geom name="shoulder" type="capsule" size="0.03" fromto="0 0 0.08 0 1 0.08" rgba="0.91 0.18 0.78 1"/>
			<site name="connection_site_1" type="sphere" size="0.05" pos="0 0 0.08" rgba="0.11 0.38 0.95 0.9"/>
			
			<body pos="0 0 0.08">
				<inertial diaginertia="0.2725 0.2725 0.2725" mass="3" pos="0 0 0"></inertial>
				<geom name="elbow" type="capsule" size="0.03" fromto="0 1 0 0 2 0" rgba="0.91 0.18 0.78 1"/>
				<site name="connection_site_2" type="sphere" size="0.05" pos="0 1 0.02" rgba="0.11 0.38 0.95 0.9"/>
				<joint name="joint_2" type="hinge" axis="0 0 1" pos="0 1 0" limited="true" range="-3 3"/>
				<site name="end_site" type="sphere" size="0.03" pos="0 2.05 0" rgba="0 1 0 1"/>
			</body>
		</body>
	</worldbody>
	
	<actuator>
        <motor joint='joint_1' name='motor_1' ctrlrange="-5 5"/>
        <motor joint='joint_2' name='motor_2' ctrlrange="-5 5"/>
	</actuator>
	
	
</mujoco>
